Workbook

Sheet Start Here
A1: SkillZeno Internship — Task 1
A3: Project | B3: Excel Sales Data Analysis
A4: Dataset source | B4: Synthetic/sample data created for learning and demonstration
A5: Period covered | B5: January–December 2025
A7: Workbook guide
A8: Step | B8: Sheet | C8: Purpose
A9: 1 | B9: Raw Data | C9: Original sample records, including deliberately inserted data-quality issues.
A10: 2 | B10: Cleaned Data | C10: Cleaned records with formulas for gross sales, discount, net sales and estimated profit.
A11: 3 | B11: Analysis | C11: Formula-driven summaries by region, category, month, and sales channel, with charts.
A12: 4 | B12: Insights | C12: A short report explaining key findings and recommendations.
A15: Before submitting
A16: • Review the Raw Data and Cleaned Data sheets to understand the cleaning decisions.
A17: • Excel will calculate formula cells when the workbook is opened in desktop Excel.
A18: • The Analysis sheet uses formulas and summary tables rather than a native Excel PivotTable object. If your mentor specifically requires an actual PivotTable, create one using the instructions in the guide.
A19: • Replace the sample data with genuine data only if you have permission and can protect private information.
A20: • Add your name and internship details to the report before submitting, if required by SkillZeno.

Sheet Raw Data
A1: Order ID | B1: Order Date | C1: Region | D1: Sales Rep | E1: Sales Channel | F1: Product | G1: Category | H1: Quantity | I1: Unit Price | J1: Discount Rate
A2: S001 | B2: 45925 | C2: East | D2: Aarav | E2: Online | F2: Pen Set | G2: Stationery | H2: 5 | I2: 6.79 | J2: 0.05
A3: S002 | B3: 45785 | C3: East | D3: Ananya | E3: Wholesale | F3: Pen Set | G3: Stationery | H3: 12 | I3: 6.76 | J3: 0.1
A4: S003 | B4: 45863 | C4: South | D4: Diya | E4: Wholesale | F4: Keyboard | G4: Electronics | H4: 9 | I4: 39.88 | J4: 0
A5: S004 | B5: 45930 | C5: North | D5: Ananya | E5: Wholesale | F5: Backpack | G5: Accessories | H5: 11 | I5: 46.86 | J5: 0
A6: S005 | B6: 45693 | C6: West | D6: Ananya | E6: Wholesale | F6: Desk | G6: Furniture | H6: 7 | I6: 190.19 | J6: 0
A7: S006 | B7: 45730 | C7: East | D7: Kabir | E7: Online | F7: Pen Set | G7: Stationery | H7: 9 | I7: 6.53 | J7: 0.05
A8: S007 | B8: 45839 | D8: Meera | E8: Online | F8: Laptop | G8: Electronics | H8: 8 | I8: 859.53 | J8: 0.05
A9: S008 | B9: 45717 | C9: East | D9: Aarav | E9: Retail | F9: Backpack | G9: Accessories | H9: 4 | I9: 48.18 | J9: 0
A10: S009 | B10: 45690 | C10: South | D10: Ishaan | E10: Wholesale | F10: Desk | G10: Furniture | H10: 4 | I10: 198.74 | J10: 0.15
A11: S010 | B11: 45815 | C11: East | D11: Ishaan | E11: Online | F11: Notebook Pack | G11: Stationery | H11: 6 | I11: 8.79 | J11: 0
A12: S011 | B12: 45683 | C12: West | D12: Ananya | E12: Online | F12: Notebook Pack | G12: Stationery | H12: 1 | I12: 9.31 | J12: 0.1
A13: S012 | B13: 45759 | C13: West | D13: Aarav | E13: Wholesale | F13: Desk | G13: Furniture | H13: 5 | I13: 196.6 | J13: 0
A14: S013 | B14: 45946 | C14: West | D14: Diya | E14: Online | F14: Backpack | G14: Accessories | H14: 11 | I14: 47.35 | J14: 0
A15: S014 | B15: 45786 | C15: North | D15: Kabir | E15: Retail | F15: Keyboard | G15: Electronics | H15: 11 | I15: 44.4 | J15: 0
A16: S015 | B16: 45819 | C16: North | D16: Ananya | E16: Retail | F16: Notebook Pack | G16: Stationery | H16: 1 | I16: 9.54 | J16: 0
A17: S016 | B17: 45786 | C17: South | D17: Diya | E17: Wholesale | F17: Pen Set | G17: Stationery | H17: 8 | I17: 7.04 | J17: 0
A18: S017 | B18: 45793 | C18: West | D18: Kabir | E18: Retail | F18: Monitor | G18: Electronics | H18: 3 | I18: 215.48 | J18: 0.05
A19: S018 | B19: 45907 | C19: West | D19: Aarav | E19: Retail | F19: Office Chair | G19: Furniture | H19: 9 | I19: 155.34 | J19: 0.1
A20: S019 | B20: 45769 | C20: East | D20: Kabir | E20: Online | F20: Headphones | G20: Furniture | H20: 8 | I20: 161.94 | J20: 0.05
... A28: S027 | B28: 45932 | C28: North | D28: Meera | E28: Online | F28: Office Chair | G28: Furniture | H28: 11 | I28: 162.61 | J28: 0
A29: S028 | B29: 45934 | C29: East | D29: Ishaan | E29: Wholesale | F29: Laptop | G29: Electronics | I29: 821.72 | J29: 0.15
A30: S029 | B30: 45955 | C30: East | D30: Aarav | E30: Wholesale | F30: Pen Set | G30: Stationery | H30: 7 | I30: 7.03 | J30: 0
A31: S030 | B31: 45675 | C31: South | D31: Kabir | E31: Online | F31: Desk | G31: Furniture | H31: 6 | I31: 179.82 | J31: 0.05
A32: S031 | B32: 45911 | C32: North | D32: Ananya | E32: Retail | F32: Desk | G32: Furniture | H32: 8 | I32: 183.48 | J32: 0
A33: S032 | B33: 45816 | C33: South | D33: Ishaan | E33: Online | F33: Office Chair | G33: Furniture | H33: 8 | I33: 146.93 | J33: 0.05
A34: S033 | B34: 45881 | C34: South | D34: Ananya | E34: Wholesale | F34: Water Bottle | G34: Accessories | H34: 9 | I34: 18.71 | J34: 0.1
A35: S034 | B35: 45731 | C35: West | D35: Ishaan | E35: Retail | F35: Keyboard | G35: Electronics | H35: 10 | I35: 44.56 | J35: 0.15
A36: S035 | B36: 45691 | C36: South | D36: Diya | E36: Retail | F36: Monitor | G36: Electronics | H36: 4 | I36: 242.95 | J36: 0
A37: S036 | B37: 45938 | C37: South | D37: Ishaan | E37: Online | F37: Notebook Pack | G37: Stationery | H37: 9 | J37: 0.1
A38: S037 | B38: 45911 | C38: North | D38: Ishaan | E38: Retail | F38: Desk | G38: Furniture | H38: 9 | I38: 186.61 | J38: 0
A39: S038 | B39: 45697 | C39: South | D39: Aarav | E39: Retail | F39: Pen Set | G39: Stationery | H39: 2 | I39: 6.88 | J39: 0.15
A40: S039 | B40: 45695 | C40: South | D40: Ananya | E40: Retail | F40: Desk | G40: Furniture | H40: 6 | I40: 185.25 | J40: 0.1
A41: S040 | B41: 45815 | C41: South | D41: Meera | E41: Online | F41: Pen Set | G41: Stationery | H41: 6 | I41: 7.01 | J41: 0.15
A42: S041 | B42: 45992 | C42: East | D42: Ananya | E42: Retail | F42: Desk | G42: Furniture | H42: 4 | I42: 182.37 | J42: 0
A43: S042 | B43: 45850 | C43: South | D43: Ishaan | E43: Online | F43: Desk | G43: Furniture | H43: 2 | I43: 187.46 | J43: 0.05
A44: S043 | B44: 45676 | C44: West | D44: Meera | E44: Retail | F44: Monitor | G44: Electronics | H44: 10 | I44: 225.24 | J44: 0
A45: S044 | B45: 45970 | C45: South | D45: Meera | E45: Online | F45: Desk | G45: Furniture | H45: 12 | I45: 188.65 | J45: 0.05
A46: S045 | B46: 45754 | C46: West | D46: Aarav | E46: Retail | F46: Office Chair | G46: Furniture | H46: 6 | I46: 149.14 | J46: 0
A47: S046 | B47: 45995 | C47: West | D47: Ananya | E47: Retail | F47: Office Chair | G47: Furniture | H47: 6 | I47: 161.12 | J47: 0.15
...

Sheet Cleaned Data
A1: Order ID | B1: Order Date | C1: Region | D1: Sales Rep | E1: Sales Channel | F1: Product | G1: Category | H1: Quantity | I1: Unit Price | J1: Discount Rate | K1: Gross Sales | L1: Discount Amount | M1: Net Sales | N1: Estimated Unit Cost | O1: Estimated Profit | P1: Data Quality Note
A2: S001 | B2: 45925 | C2: East | D2: Aarav | E2: Online | F2: Pen Set | G2: Stationery | H2: 5 | I2: 6.79 | J2: 0.05 | K2: =H2*I2 | L2: =K2*J2 | M2: =K2-L2 | N2: =IF(F2="Laptop",620,IF(F2="Headphones",28,IF(F2="Keyboard",22,IF(F2="Office Chair",95,IF(F2="Desk",110,IF(F2="Notebook Pack",4,IF(F2="Pen Set",3,IF(F2="Water Bottle",8,IF(F2="Backpack",24,IF(F2="Monitor",140,0)))))))))) | O2: =M2-(H2*N2) | P2: Checked; no issue detected
A3: S002 | B3: 45785 | C3: East | D3: Ananya | E3: Wholesale | F3: Pen Set | G3: Stationery | H3: 12 | I3: 6.76 | J3: 0.1 | K3: =H3*I3 | L3: =K3*J3 | M3: =K3-L3 | N3: =IF(F3="Laptop",620,IF(F3="Headphones",28,IF(F3="Keyboard",22,IF(F3="Office Chair",95,IF(F3="Desk",110,IF(F3="Notebook Pack",4,IF(F3="Pen Set",3,IF(F3="Water Bottle",8,IF(F3="Backpack",24,IF(F3="Monitor",140,0)))))))))) | O3: =M3-(H3*N3) | P3: Checked; no issue detected
A4: S003 | B4: 45863 | C4: South | D4: Diya | E4: Wholesale | F4: Keyboard | G4: Electronics | H4: 9 | I4: 39.88 | J4: 0 | K4: =H4*I4 | L4: =K4*J4 | M4: =K4-L4 | N4: =IF(F4="Laptop",620,IF(F4="Headphones",28,IF(F4="Keyboard",22,IF(F4="Office Chair",95,IF(F4="Desk",110,IF(F4="Notebook Pack",4,IF(F4="Pen Set",3,IF(F4="Water Bottle",8,IF(F4="Backpack",24,IF(F4="Monitor",140,0)))))))))) | O4: =M4-(H4*N4) | P4: Checked; no issue detected
A5: S004 | B5: 45930 | C5: North | D5: Ananya | E5: Wholesale | F5: Backpack | G5: Accessories | H5: 11 | I5: 46.86 | J5: 0 | K5: =H5*I5 | L5: =K5*J5 | M5: =K5-L5 | N5: =IF(F5="Laptop",620,IF(F5="Headphones",28,IF(F5="Keyboard",22,IF(F5="Office Chair",95,IF(F5="Desk",110,IF(F5="Notebook Pack",4,IF(F5="Pen Set",3,IF(F5="Water Bottle",8,IF(F5="Backpack",24,IF(F5="Monitor",140,0)))))))))) | O5: =M5-(H5*N5) | P5: Checked; no issue detected
A6: S005 | B6: 45693 | C6: West | D6: Ananya | E6: Wholesale | F6: Desk | G6: Furniture | H6: 7 | I6: 190.19 | J6: 0 | K6: =H6*I6 | L6: =K6*J6 | M6: =K6-L6 | N6: =IF(F6="Laptop",620,IF(F6="Headphones",28,IF(F6="Keyboard",22,IF(F6="Office Chair",95,IF(F6="Desk",110,IF(F6="Notebook Pack",4,IF(F6="Pen Set",3,IF(F6="Water Bottle",8,IF(F6="Backpack",24,IF(F6="Monitor",140,0)))))))))) | O6: =M6-(H6*N6) | P6: Checked; no issue detected
A7: S006 | B7: 45730 | C7: East | D7: Kabir | E7: Online | F7: Pen Set | G7: Stationery | H7: 9 | I7: 6.53 | J7: 0.05 | K7: =H7*I7 | L7: =K7*J7 | M7: =K7-L7 | N7: =IF(F7="Laptop",620,IF(F7="Headphones",28,IF(F7="Keyboard",22,IF(F7="Office Chair",95,IF(F7="Desk",110,IF(F7="Notebook Pack",4,IF(F7="Pen Set",3,IF(F7="Water Bottle",8,IF(F7="Backpack",24,IF(F7="Monitor",140,0)))))))))) | O7: =M7-(H7*N7) | P7: Checked; no issue detected
A8: S007 | B8: 45839 | C8: Unknown | D8: Meera | E8: Online | F8: Laptop | G8: Electronics | H8: 8 | I8: 859.53 | J8: 0.05 | K8: =H8*I8 | L8: =K8*J8 | M8: =K8-L8 | N8: =IF(F8="Laptop",620,IF(F8="Headphones",28,IF(F8="Keyboard",22,IF(F8="Office Chair",95,IF(F8="Desk",110,IF(F8="Notebook Pack",4,IF(F8="Pen Set",3,IF(F8="Water Bottle",8,IF(F8="Backpack",24,IF(F8="Monitor",140,0)))))))))) | O8: =M8-(H8*N8) | P8: Missing region set to Unknown
A9: S008 | B9: 45717 | C9: East | D9: Aarav | E9: Retail | F9: Backpack | G9: Accessories | H9: 4 | I9: 48.18 | J9: 0 | K9: =H9*I9 | L9: =K9*J9 | M9: =K9-L9 | N9: =IF(F9="Laptop",620,IF(F9="Headphones",28,IF(F9="Keyboard",22,IF(F9="Office Chair",95,IF(F9="Desk",110,IF(F9="Notebook Pack",4,IF(F9="Pen Set",3,IF(F9="Water Bottle",8,IF(F9="Backpack",24,IF(F9="Monitor",140,0)))))))))) | O9: =M9-(H9*N9) | P9: Checked; no issue detected
A10: S009 | B10: 45690 | C10: South | D10: Ishaan | E10: Wholesale | F10: Desk | G10: Furniture | H10: 4 | I10: 198.74 | J10: 0.15 | K10: =H10*I10 | L10: =K10*J10 | M10: =K10-L10 | N10: =IF(F10="Laptop",620,IF(F10="Headphones",28,IF(F10="Keyboard",22,IF(F10="Office Chair",95,IF(F10="Desk",110,IF(F10="Notebook Pack",4,IF(F10="Pen Set",3,IF(F10="Water Bottle",8,IF(F10="Backpack",24,IF(F10="Monitor",140,0)))))))))) | O10: =M10-(H10*N10) | P10: Checked; no issue detected
A11: S010 | B11: 45815 | C11: East | D11: Ishaan | E11: Online | F11: Notebook Pack | G11: Stationery | H11: 6 | I11: 8.79 | J11: 0 | K11: =H11*I11 | L11: =K11*J11 | M11: =K11-L11 | N11: =IF(F11="Laptop",620,IF(F11="Headphones",28,IF(F11="Keyboard",22,IF(F11="Office Chair",95,IF(F11="Desk",110,IF(F11="Notebook Pack",4,IF(F11="Pen Set",3,IF(F11="Water Bottle",8,IF(F11="Backpack",24,IF(F11="Monitor",140,0)))))))))) | O11: =M11-(H11*N11) | P11: Checked; no issue detected
A12: S011 | B12: 45683 | C12: West | D12: Ananya | E12: Online | F12: Notebook Pack | G12: Stationery | H12: 1 | I12: 9.31 | J12: 0.1 | K12: =H12*I12 | L12: =K12*J12 | M12: =K12-L12 | N12: =IF(F12="Laptop",620,IF(F12="Headphones",28,IF(F12="Keyboard",22,IF(F12="Office Chair",95,IF(F12="Desk",110,IF(F12="Notebook Pack",4,IF(F12="Pen Set",3,IF(F12="Water Bottle",8,IF(F12="Backpack",24,IF(F12="Monitor",140,0)))))))))) | O12: =M12-(H12*N12) | P12: Checked; no issue detected
A13: S012 | B13: 45759 | C13: West | D13: Aarav | E13: Wholesale | F13: Desk | G13: Furniture | H13: 5 | I13: 196.6 | J13: 0 | K13: =H13*I13 | L13: =K13*J13 | M13: =K13-L13 | N13: =IF(F13="Laptop",620,IF(F13="Headphones",28,IF(F13="Keyboard",22,IF(F13="Office Chair",95,IF(F13="Desk",110,IF(F13="Notebook Pack",4,IF(F13="Pen Set",3,IF(F13="Water Bottle",8,IF(F13="Backpack",24,IF(F13="Monitor",140,0)))))))))) | O13: =M13-(H13*N13) | P13: Checked; no issue detected
... A81: S080 | B81: 45678 | C81: South | D81: Diya | E81: Wholesale | F81: Office Chair | G81: Furniture | H81: 6 | I81: 149.08 | J81: 0.05 | K81: =H81*I81 | L81: =K81*J81 | M81: =K81-L81 | N81: =IF(F81="Laptop",620,IF(F81="Headphones",28,IF(F81="Keyboard",22,IF(F81="Office Chair",95,IF(F81="Desk",110,IF(F81="Notebook Pack",4,IF(F81="Pen Set",3,IF(F81="Water Bottle",8,IF(F81="Backpack",24,IF(F81="Monitor",140,0)))))))))) | O81: =M81-(H81*N81) | P81: Checked; no issue detected

Sheet Analysis
A1: Sales Analysis Dashboard
A2: Formula-driven summaries based on the Cleaned Data sheet
A4: Total Net Sales | C4: Total Orders | E4: Units Sold | G4: Estimated Profit
A5: =SUM('Cleaned Data'!M2:M81) | C5: =COUNTA('Cleaned Data'!A2:A81) | E5: =SUM('Cleaned Data'!H2:H81) | G5: =SUM('Cleaned Data'!O2:O81)
A8: Net Sales by Region | D8: Net Sales by Category | G8: Net Sales by Channel
A9: Region | B9: Net Sales | D9: Category | E9: Net Sales | G9: Channel | H9: Net Sales
A10: East | B10: =SUMIF('Cleaned Data'!$C$2:$C$81,A10,'Cleaned Data'!$M$2:$M$81) | D10: Accessories | E10: =SUMIF('Cleaned Data'!$G$2:$G$81,D10,'Cleaned Data'!$M$2:$M$81) | G10: Online | H10: =SUMIF('Cleaned Data'!$E$2:$E$81,G10,'Cleaned Data'!$M$2:$M$81)
A11: North | B11: =SUMIF('Cleaned Data'!$C$2:$C$81,A11,'Cleaned Data'!$M$2:$M$81) | D11: Electronics | E11: =SUMIF('Cleaned Data'!$G$2:$G$81,D11,'Cleaned Data'!$M$2:$M$81) | G11: Retail | H11: =SUMIF('Cleaned Data'!$E$2:$E$81,G11,'Cleaned Data'!$M$2:$M$81)
A12: South | B12: =SUMIF('Cleaned Data'!$C$2:$C$81,A12,'Cleaned Data'!$M$2:$M$81) | D12: Furniture | E12: =SUMIF('Cleaned Data'!$G$2:$G$81,D12,'Cleaned Data'!$M$2:$M$81) | G12: Wholesale | H12: =SUMIF('Cleaned Data'!$E$2:$E$81,G12,'Cleaned Data'!$M$2:$M$81)
A13: West | B13: =SUMIF('Cleaned Data'!$C$2:$C$81,A13,'Cleaned Data'!$M$2:$M$81) | D13: Stationery | E13: =SUMIF('Cleaned Data'!$G$2:$G$81,D13,'Cleaned Data'!$M$2:$M$81)
A14: Unknown | B14: =SUMIF('Cleaned Data'!$C$2:$C$81,A14,'Cleaned Data'!$M$2:$M$81)
A18: Monthly Net Sales
A19: Month | B19: Net Sales
A20: 45658 | B20: =SUMIFS('Cleaned Data'!$M$2:$M$81,'Cleaned Data'!$B$2:$B$81,">="&A20,'Cleaned Data'!$B$2:$B$81,"<"&EDATE(A20,1))
A21: 45689 | B21: =SUMIFS('Cleaned Data'!$M$2:$M$81,'Cleaned Data'!$B$2:$B$81,">="&A21,'Cleaned Data'!$B$2:$B$81,"<"&EDATE(A21,1))
A22: 45717 | B22: =SUMIFS('Cleaned Data'!$M$2:$M$81,'Cleaned Data'!$B$2:$B$81,">="&A22,'Cleaned Data'!$B$2:$B$81,"<"&EDATE(A22,1))
A23: 45748 | B23: =SUMIFS('Cleaned Data'!$M$2:$M$81,'Cleaned Data'!$B$2:$B$81,">="&A23,'Cleaned Data'!$B$2:$B$81,"<"&EDATE(A23,1))
A24: 45778 | B24: =SUMIFS('Cleaned Data'!$M$2:$M$81,'Cleaned Data'!$B$2:$B$81,">="&A24,'Cleaned Data'!$B$2:$B$81,"<"&EDATE(A24,1))
A25: 45809 | B25: =SUMIFS('Cleaned Data'!$M$2:$M$81,'Cleaned Data'!$B$2:$B$81,">="&A25,'Cleaned Data'!$B$2:$B$81,"<"&EDATE(A25,1))
A26: 45839 | B26: =SUMIFS('Cleaned Data'!$M$2:$M$81,'Cleaned Data'!$B$2:$B$81,">="&A26,'Cleaned Data'!$B$2:$B$81,"<"&EDATE(A26,1))
A27: 45870 | B27: =SUMIFS('Cleaned Data'!$M$2:$M$81,'Cleaned Data'!$B$2:$B$81,">="&A27,'Cleaned Data'!$B$2:$B$81,"<"&EDATE(A27,1))
A28: 45901 | B28: =SUMIFS('Cleaned Data'!$M$2:$M$81,'Cleaned Data'!$B$2:$B$81,">="&A28,'Cleaned Data'!$B$2:$B$81,"<"&EDATE(A28,1))
A29: 45931 | B29: =SUMIFS('Cleaned Data'!$M$2:$M$81,'Cleaned Data'!$B$2:$B$81,">="&A29,'Cleaned Data'!$B$2:$B$81,"<"&EDATE(A29,1))
A30: 45962 | B30: =SUMIFS('Cleaned Data'!$M$2:$M$81,'Cleaned Data'!$B$2:$B$81,">="&A30,'Cleaned Data'!$B$2:$B$81,"<"&EDATE(A30,1))
A31: 45992 | B31: =SUMIFS('Cleaned Data'!$M$2:$M$81,'Cleaned Data'!$B$2:$B$81,">="&A31,'Cleaned Data'!$B$2:$B$81,"<"&EDATE(A31,1))

Sheet Insights
A1: Sales Data Analysis — Findings & Recommendations
A3: Objective | B3: Analyze sample 2025 sales transactions to understand performance by region, category, channel and month.
A5: Questions to answer
A6: 1. | B6: Which region generated the highest net sales?
A7: 2. | B7: Which product category contributed the most net sales?
A8: 3. | B8: How do sales vary across Online, Retail and Wholesale channels?
A9: 4. | B9: Which months show stronger or weaker sales?
A10: 5. | B10: What data-quality issues were corrected?
A13: Findings template
A14: Region | B14: Use the Region summary and chart on the Analysis sheet. Name the highest and lowest regions after Excel recalculates.
A15: Category | B15: Use the Category summary and pie chart to identify the largest sales contributor.
A16: Channel | B16: Compare Online, Retail and Wholesale totals. Consider whether channel performance may be affected by order size or discounts.
A17: Monthly trend | B17: Review the monthly line chart. Note any peaks or dips; do not claim a cause unless supported by more data.
A18: Data cleaning | B18: Document how missing values, inconsistent capitalization/whitespace, invalid values and duplicate rows were handled.
A21: Conclusion (edit after reviewing the results)
A22: The analysis demonstrates how spreadsheet cleaning, formulas, filters, summaries and charts can convert transaction-level data into useful business information. Replace this paragraph with 2–3 specific findings from your calculated results.
A26: Limitations
A27: This is synthetic demonstration data, not verified company sales. Estimated profit uses fixed reference costs and should not be treated as actual financial performance.
